[2024-10-24T18:07:54.856+0000] {local_task_job_runner.py:120} INFO - ::group::Pre task execution logs
[2024-10-24T18:07:54.883+0000] {taskinstance.py:2076} INFO - Dependencies all met for dep_context=non-requeueable deps ti=<TaskInstance: Nikita_Lapshin_experiment.train_and_log_model scheduled__2024-10-23T01:00:00+00:00 [queued]>
[2024-10-24T18:07:54.891+0000] {taskinstance.py:2076} INFO - Dependencies all met for dep_context=requeueable deps ti=<TaskInstance: Nikita_Lapshin_experiment.train_and_log_model scheduled__2024-10-23T01:00:00+00:00 [queued]>
[2024-10-24T18:07:54.893+0000] {taskinstance.py:2306} INFO - Starting attempt 1 of 4
[2024-10-24T18:07:54.905+0000] {taskinstance.py:2330} INFO - Executing <Task(PythonOperator): train_and_log_model> on 2024-10-23 01:00:00+00:00
[2024-10-24T18:07:54.916+0000] {standard_task_runner.py:64} INFO - Started process 293 to run task
[2024-10-24T18:07:54.928+0000] {standard_task_runner.py:90} INFO - Running: ['***', 'tasks', 'run', 'Nikita_Lapshin_experiment', 'train_and_log_model', 'scheduled__2024-10-23T01:00:00+00:00', '--job-id', '160', '--raw', '--subdir', 'DAGS_FOLDER/HW2.py', '--cfg-path', '/tmp/tmpp57a9lyw']
[2024-10-24T18:07:54.938+0000] {standard_task_runner.py:91} INFO - Job 160: Subtask train_and_log_model
[2024-10-24T18:07:55.015+0000] {task_command.py:426} INFO - Running <TaskInstance: Nikita_Lapshin_experiment.train_and_log_model scheduled__2024-10-23T01:00:00+00:00 [running]> on host 701639cb5e9f
[2024-10-24T18:07:55.111+0000] {taskinstance.py:2648} INFO - Exporting env vars: AIRFLOW_CTX_DAG_OWNER='Lapshin Nikita' AIRFLOW_CTX_DAG_ID='Nikita_Lapshin_experiment' AIRFLOW_CTX_TASK_ID='train_and_log_model' AIRFLOW_CTX_EXECUTION_DATE='2024-10-23T01:00:00+00:00' AIRFLOW_CTX_TRY_NUMBER='1' AIRFLOW_CTX_DAG_RUN_ID='scheduled__2024-10-23T01:00:00+00:00'
[2024-10-24T18:07:55.114+0000] {taskinstance.py:430} INFO - ::endgroup::
[2024-10-24T18:07:55.133+0000] {s3.py:1422} INFO - Downloading source S3 file from Bucket mlops-2 with path datasets/prepared_data.csv
[2024-10-24T18:07:55.143+0000] {base.py:84} INFO - Using connection ID 's3_connection' for task execution.
[2024-10-24T18:07:55.144+0000] {connection_wrapper.py:388} INFO - AWS Connection (conn_id='s3_connection', conn_type='aws') credentials retrieved from login and password.
[2024-10-24T18:08:01.607+0000] {logging_mixin.py:188} INFO - result1
[2024-10-24T18:08:01.688+0000] {logging_mixin.py:188} WARNING - 2024/10/24 18:08:01 WARNING mlflow.utils.git_utils: Failed to import Git (the Git executable is probably not on your PATH), so Git SHA is not available. Error: Failed to initialize: Bad git executable.
The git executable must be specified in one of the following ways:
    - be included in your $PATH
    - be set via $GIT_PYTHON_GIT_EXECUTABLE
    - explicitly set via git.refresh(<full-path-to-git-executable>)

All git commands will error until this is rectified.

This initial message can be silenced or aggravated in the future by setting the
$GIT_PYTHON_REFRESH environment variable. Use one of the following values:
    - quiet|q|silence|s|silent|none|n|0: for no message or exception
    - warn|w|warning|log|l|1: for a warning message (logging level CRITICAL, displayed by default)
    - error|e|exception|raise|r|2: for a raised exception

Example:
    export GIT_PYTHON_REFRESH=quiet
[2024-10-24T18:08:18.501+0000] {logging_mixin.py:188} INFO - result2 random_forest
[2024-10-24T18:08:27.136+0000] {credentials.py:1147} INFO - Found credentials in environment variables.
[2024-10-24T18:17:44.079+0000] {logging_mixin.py:188} WARNING - 2024/10/24 18:17:44 INFO mlflow.tracking._tracking_service.client: üèÉ View run random_forest_run at: http://mlflow-service:5000/#/experiments/589296618587154829/runs/e6214b240d4a4d6091b60642c8f57bbd.
[2024-10-24T18:17:44.087+0000] {logging_mixin.py:188} WARNING - 2024/10/24 18:17:44 INFO mlflow.tracking._tracking_service.client: üß™ View experiment at: http://mlflow-service:5000/#/experiments/589296618587154829.
[2024-10-24T18:17:44.105+0000] {logging_mixin.py:188} WARNING - 2024/10/24 18:17:44 INFO mlflow.tracking._tracking_service.client: üèÉ View run @GodSiemens at: http://mlflow-service:5000/#/experiments/589296618587154829/runs/eb82e071d777428fa48734012e4c744b.
[2024-10-24T18:17:44.105+0000] {logging_mixin.py:188} WARNING - 2024/10/24 18:17:44 INFO mlflow.tracking._tracking_service.client: üß™ View experiment at: http://mlflow-service:5000/#/experiments/589296618587154829.
[2024-10-24T18:17:44.110+0000] {taskinstance.py:441} INFO - ::group::Post task execution logs
[2024-10-24T18:17:44.114+0000] {taskinstance.py:2905} ERROR - Task failed with exception
Traceback (most recent call last):
  File "/home/airflow/.local/lib/python3.10/site-packages/urllib3/connectionpool.py", line 537, in _make_request
    response = conn.getresponse()
  File "/home/airflow/.local/lib/python3.10/site-packages/urllib3/connection.py", line 461, in getresponse
    httplib_response = super().getresponse()
  File "/usr/local/lib/python3.10/http/client.py", line 1375, in getresponse
    response.begin()
  File "/usr/local/lib/python3.10/http/client.py", line 318, in begin
    version, status, reason = self._read_status()
  File "/usr/local/lib/python3.10/http/client.py", line 279, in _read_status
    line = str(self.fp.readline(_MAXLINE + 1), "iso-8859-1")
  File "/usr/local/lib/python3.10/socket.py", line 705, in readinto
    return self._sock.recv_into(b)
  File "/usr/local/lib/python3.10/ssl.py", line 1307, in recv_into
    return self.read(nbytes, buffer)
  File "/usr/local/lib/python3.10/ssl.py", line 1163, in read
    return self._sslobj.read(len, buffer)
TimeoutError: The read operation timed out

The above exception was the direct cause of the following exception:

Traceback (most recent call last):
  File "/home/airflow/.local/lib/python3.10/site-packages/botocore/httpsession.py", line 464, in send
    urllib_response = conn.urlopen(
  File "/home/airflow/.local/lib/python3.10/site-packages/urllib3/connectionpool.py", line 845, in urlopen
    retries = retries.increment(
  File "/home/airflow/.local/lib/python3.10/site-packages/urllib3/util/retry.py", line 445, in increment
    raise reraise(type(error), error, _stacktrace)
  File "/home/airflow/.local/lib/python3.10/site-packages/urllib3/util/util.py", line 39, in reraise
    raise value
  File "/home/airflow/.local/lib/python3.10/site-packages/urllib3/connectionpool.py", line 791, in urlopen
    response = self._make_request(
  File "/home/airflow/.local/lib/python3.10/site-packages/urllib3/connectionpool.py", line 539, in _make_request
    self._raise_timeout(err=e, url=url, timeout_value=read_timeout)
  File "/home/airflow/.local/lib/python3.10/site-packages/urllib3/connectionpool.py", line 371, in _raise_timeout
    raise ReadTimeoutError(
urllib3.exceptions.ReadTimeoutError: AWSHTTPSConnectionPool(host='storage.yandexcloud.net', port=443): Read timed out. (read timeout=60)

During handling of the above exception, another exception occurred:

Traceback (most recent call last):
  File "/home/airflow/.local/lib/python3.10/site-packages/airflow/models/taskinstance.py", line 465, in _execute_task
    result = _execute_callable(context=context, **execute_callable_kwargs)
  File "/home/airflow/.local/lib/python3.10/site-packages/airflow/models/taskinstance.py", line 432, in _execute_callable
    return execute_callable(context=context, **execute_callable_kwargs)
  File "/home/airflow/.local/lib/python3.10/site-packages/airflow/models/baseoperator.py", line 401, in wrapper
    return func(self, *args, **kwargs)
  File "/home/airflow/.local/lib/python3.10/site-packages/airflow/operators/python.py", line 235, in execute
    return_value = self.execute_callable()
  File "/home/airflow/.local/lib/python3.10/site-packages/airflow/operators/python.py", line 252, in execute_callable
    return self.python_callable(*self.op_args, **self.op_kwargs)
  File "/opt/airflow/dags/HW2.py", line 124, in train_and_log_model
    mlflow.sklearn.log_model(model, model_name, input_example=input_example)
  File "/home/airflow/.local/lib/python3.10/site-packages/mlflow/sklearn/__init__.py", line 412, in log_model
    return Model.log(
  File "/home/airflow/.local/lib/python3.10/site-packages/mlflow/models/model.py", line 714, in log
    mlflow.tracking.fluent.log_artifacts(local_path, mlflow_model.artifact_path, run_id)
  File "/home/airflow/.local/lib/python3.10/site-packages/mlflow/tracking/fluent.py", line 1147, in log_artifacts
    MlflowClient().log_artifacts(run_id, local_dir, artifact_path)
  File "/home/airflow/.local/lib/python3.10/site-packages/mlflow/tracking/client.py", line 1962, in log_artifacts
    self._tracking_client.log_artifacts(run_id, local_dir, artifact_path)
  File "/home/airflow/.local/lib/python3.10/site-packages/mlflow/tracking/_tracking_service/client.py", line 843, in log_artifacts
    self._get_artifact_repo(run_id).log_artifacts(local_dir, artifact_path)
  File "/home/airflow/.local/lib/python3.10/site-packages/mlflow/store/artifact/s3_artifact_repo.py", line 194, in log_artifacts
    self._upload_file(
  File "/home/airflow/.local/lib/python3.10/site-packages/mlflow/store/artifact/s3_artifact_repo.py", line 169, in _upload_file
    s3_client.upload_file(Filename=local_file, Bucket=bucket, Key=key, ExtraArgs=extra_args)
  File "/home/airflow/.local/lib/python3.10/site-packages/boto3/s3/inject.py", line 145, in upload_file
    return transfer.upload_file(
  File "/home/airflow/.local/lib/python3.10/site-packages/boto3/s3/transfer.py", line 371, in upload_file
    future.result()
  File "/home/airflow/.local/lib/python3.10/site-packages/s3transfer/futures.py", line 103, in result
    return self._coordinator.result()
  File "/home/airflow/.local/lib/python3.10/site-packages/s3transfer/futures.py", line 266, in result
    raise self._exception
  File "/home/airflow/.local/lib/python3.10/site-packages/s3transfer/tasks.py", line 139, in __call__
    return self._execute_main(kwargs)
  File "/home/airflow/.local/lib/python3.10/site-packages/s3transfer/tasks.py", line 162, in _execute_main
    return_value = self._main(**kwargs)
  File "/home/airflow/.local/lib/python3.10/site-packages/s3transfer/upload.py", line 793, in _main
    response = client.upload_part(
  File "/home/airflow/.local/lib/python3.10/site-packages/botocore/client.py", line 565, in _api_call
    return self._make_api_call(operation_name, kwargs)
  File "/home/airflow/.local/lib/python3.10/site-packages/botocore/client.py", line 1001, in _make_api_call
    http, parsed_response = self._make_request(
  File "/home/airflow/.local/lib/python3.10/site-packages/botocore/client.py", line 1027, in _make_request
    return self._endpoint.make_request(operation_model, request_dict)
  File "/home/airflow/.local/lib/python3.10/site-packages/botocore/endpoint.py", line 119, in make_request
    return self._send_request(request_dict, operation_model)
  File "/home/airflow/.local/lib/python3.10/site-packages/botocore/endpoint.py", line 202, in _send_request
    while self._needs_retry(
  File "/home/airflow/.local/lib/python3.10/site-packages/botocore/endpoint.py", line 354, in _needs_retry
    responses = self._event_emitter.emit(
  File "/home/airflow/.local/lib/python3.10/site-packages/botocore/hooks.py", line 412, in emit
    return self._emitter.emit(aliased_event_name, **kwargs)
  File "/home/airflow/.local/lib/python3.10/site-packages/botocore/hooks.py", line 256, in emit
    return self._emit(event_name, kwargs)
  File "/home/airflow/.local/lib/python3.10/site-packages/botocore/hooks.py", line 239, in _emit
    response = handler(**kwargs)
  File "/home/airflow/.local/lib/python3.10/site-packages/botocore/retryhandler.py", line 207, in __call__
    if self._checker(**checker_kwargs):
  File "/home/airflow/.local/lib/python3.10/site-packages/botocore/retryhandler.py", line 284, in __call__
    should_retry = self._should_retry(
  File "/home/airflow/.local/lib/python3.10/site-packages/botocore/retryhandler.py", line 320, in _should_retry
    return self._checker(attempt_number, response, caught_exception)
  File "/home/airflow/.local/lib/python3.10/site-packages/botocore/retryhandler.py", line 363, in __call__
    checker_response = checker(
  File "/home/airflow/.local/lib/python3.10/site-packages/botocore/retryhandler.py", line 247, in __call__
    return self._check_caught_exception(
  File "/home/airflow/.local/lib/python3.10/site-packages/botocore/retryhandler.py", line 416, in _check_caught_exception
    raise caught_exception
  File "/home/airflow/.local/lib/python3.10/site-packages/botocore/endpoint.py", line 281, in _do_get_response
    http_response = self._send(request)
  File "/home/airflow/.local/lib/python3.10/site-packages/botocore/endpoint.py", line 377, in _send
    return self.http_session.send(request)
  File "/home/airflow/.local/lib/python3.10/site-packages/botocore/httpsession.py", line 501, in send
    raise ReadTimeoutError(endpoint_url=request.url, error=e)
botocore.exceptions.ReadTimeoutError: Read timeout on endpoint URL: "https://storage.yandexcloud.net/mlops-2/589296618587154829/e6214b240d4a4d6091b60642c8f57bbd/artifacts/random_forest/model.pkl?uploadId=0006253CE3B2EDBB&partNumber=1"
[2024-10-24T18:17:44.173+0000] {taskinstance.py:1206} INFO - Marking task as UP_FOR_RETRY. dag_id=Nikita_Lapshin_experiment, task_id=train_and_log_model, run_id=scheduled__2024-10-23T01:00:00+00:00, execution_date=20241023T010000, start_date=20241024T180754, end_date=20241024T181744
[2024-10-24T18:17:44.212+0000] {standard_task_runner.py:110} ERROR - Failed to execute job 160 for task train_and_log_model (Read timeout on endpoint URL: "https://storage.yandexcloud.net/mlops-2/589296618587154829/e6214b240d4a4d6091b60642c8f57bbd/artifacts/random_forest/model.pkl?uploadId=0006253CE3B2EDBB&partNumber=1"; 293)
[2024-10-24T18:17:44.289+0000] {local_task_job_runner.py:243} INFO - Task exited with return code 1
[2024-10-24T18:17:44.331+0000] {taskinstance.py:3503} INFO - 0 downstream tasks scheduled from follow-on schedule check
[2024-10-24T18:17:44.332+0000] {local_task_job_runner.py:222} INFO - ::endgroup::
