[2024-10-24T20:24:04.197+0000] {local_task_job_runner.py:120} INFO - ::group::Pre task execution logs
[2024-10-24T20:24:04.212+0000] {taskinstance.py:2076} INFO - Dependencies all met for dep_context=non-requeueable deps ti=<TaskInstance: Nikita_Lapshin_experiment.init manual__2024-10-24T20:21:51.943577+00:00 [queued]>
[2024-10-24T20:24:04.218+0000] {taskinstance.py:2076} INFO - Dependencies all met for dep_context=requeueable deps ti=<TaskInstance: Nikita_Lapshin_experiment.init manual__2024-10-24T20:21:51.943577+00:00 [queued]>
[2024-10-24T20:24:04.219+0000] {taskinstance.py:2306} INFO - Starting attempt 3 of 4
[2024-10-24T20:24:04.228+0000] {taskinstance.py:2330} INFO - Executing <Task(PythonOperator): init> on 2024-10-24 20:21:51.943577+00:00
[2024-10-24T20:24:04.257+0000] {standard_task_runner.py:64} INFO - Started process 799 to run task
[2024-10-24T20:24:04.299+0000] {standard_task_runner.py:90} INFO - Running: ['***', 'tasks', 'run', 'Nikita_Lapshin_experiment', 'init', 'manual__2024-10-24T20:21:51.943577+00:00', '--job-id', '167', '--raw', '--subdir', 'DAGS_FOLDER/HW2.py', '--cfg-path', '/tmp/tmphfmzktpl']
[2024-10-24T20:24:04.332+0000] {standard_task_runner.py:91} INFO - Job 167: Subtask init
[2024-10-24T20:24:04.467+0000] {task_command.py:426} INFO - Running <TaskInstance: Nikita_Lapshin_experiment.init manual__2024-10-24T20:21:51.943577+00:00 [running]> on host 701639cb5e9f
[2024-10-24T20:24:04.803+0000] {taskinstance.py:2648} INFO - Exporting env vars: AIRFLOW_CTX_DAG_OWNER='Lapshin Nikita' AIRFLOW_CTX_DAG_ID='Nikita_Lapshin_experiment' AIRFLOW_CTX_TASK_ID='init' AIRFLOW_CTX_EXECUTION_DATE='2024-10-24T20:21:51.943577+00:00' AIRFLOW_CTX_TRY_NUMBER='3' AIRFLOW_CTX_DAG_RUN_ID='manual__2024-10-24T20:21:51.943577+00:00'
[2024-10-24T20:24:04.809+0000] {taskinstance.py:430} INFO - ::endgroup::
[2024-10-24T20:24:04.890+0000] {taskinstance.py:441} INFO - ::group::Post task execution logs
[2024-10-24T20:24:04.891+0000] {taskinstance.py:2905} ERROR - Task failed with exception
Traceback (most recent call last):
  File "/home/airflow/.local/lib/python3.10/site-packages/airflow/models/taskinstance.py", line 465, in _execute_task
    result = _execute_callable(context=context, **execute_callable_kwargs)
  File "/home/airflow/.local/lib/python3.10/site-packages/airflow/models/taskinstance.py", line 432, in _execute_callable
    return execute_callable(context=context, **execute_callable_kwargs)
  File "/home/airflow/.local/lib/python3.10/site-packages/airflow/models/baseoperator.py", line 401, in wrapper
    return func(self, *args, **kwargs)
  File "/home/airflow/.local/lib/python3.10/site-packages/airflow/operators/python.py", line 235, in execute
    return_value = self.execute_callable()
  File "/home/airflow/.local/lib/python3.10/site-packages/airflow/operators/python.py", line 252, in execute_callable
    return self.python_callable(*self.op_args, **self.op_kwargs)
  File "/opt/airflow/dags/HW2.py", line 49, in init
    configure_mlflow()
  File "/opt/airflow/dags/HW2.py", line 45, in configure_mlflow
    os.environ[key] = Variable.get(key)
  File "/home/airflow/.local/lib/python3.10/site-packages/airflow/models/variable.py", line 143, in get
    raise KeyError(f"Variable {key} does not exist")
KeyError: 'Variable MLFLOW_TRACKING_URI does not exist'
[2024-10-24T20:24:04.905+0000] {taskinstance.py:1206} INFO - Marking task as UP_FOR_RETRY. dag_id=Nikita_Lapshin_experiment, task_id=init, run_id=manual__2024-10-24T20:21:51.943577+00:00, execution_date=20241024T202151, start_date=20241024T202404, end_date=20241024T202404
[2024-10-24T20:24:04.935+0000] {standard_task_runner.py:110} ERROR - Failed to execute job 167 for task init ('Variable MLFLOW_TRACKING_URI does not exist'; 799)
[2024-10-24T20:24:05.002+0000] {local_task_job_runner.py:243} INFO - Task exited with return code 1
[2024-10-24T20:24:05.168+0000] {taskinstance.py:3503} INFO - 0 downstream tasks scheduled from follow-on schedule check
[2024-10-24T20:24:05.171+0000] {local_task_job_runner.py:222} INFO - ::endgroup::
