[2024-10-24T20:23:00.380+0000] {local_task_job_runner.py:120} INFO - ::group::Pre task execution logs
[2024-10-24T20:23:00.390+0000] {taskinstance.py:2076} INFO - Dependencies all met for dep_context=non-requeueable deps ti=<TaskInstance: Nikita_Lapshin_experiment.init manual__2024-10-24T20:21:51.943577+00:00 [queued]>
[2024-10-24T20:23:00.395+0000] {taskinstance.py:2076} INFO - Dependencies all met for dep_context=requeueable deps ti=<TaskInstance: Nikita_Lapshin_experiment.init manual__2024-10-24T20:21:51.943577+00:00 [queued]>
[2024-10-24T20:23:00.395+0000] {taskinstance.py:2306} INFO - Starting attempt 2 of 4
[2024-10-24T20:23:00.405+0000] {taskinstance.py:2330} INFO - Executing <Task(PythonOperator): init> on 2024-10-24 20:21:51.943577+00:00
[2024-10-24T20:23:00.433+0000] {standard_task_runner.py:64} INFO - Started process 763 to run task
[2024-10-24T20:23:00.442+0000] {standard_task_runner.py:90} INFO - Running: ['***', 'tasks', 'run', 'Nikita_Lapshin_experiment', 'init', 'manual__2024-10-24T20:21:51.943577+00:00', '--job-id', '166', '--raw', '--subdir', 'DAGS_FOLDER/HW2.py', '--cfg-path', '/tmp/tmps0n5qapu']
[2024-10-24T20:23:00.446+0000] {standard_task_runner.py:91} INFO - Job 166: Subtask init
[2024-10-24T20:23:00.513+0000] {task_command.py:426} INFO - Running <TaskInstance: Nikita_Lapshin_experiment.init manual__2024-10-24T20:21:51.943577+00:00 [running]> on host 701639cb5e9f
[2024-10-24T20:23:00.594+0000] {taskinstance.py:2648} INFO - Exporting env vars: AIRFLOW_CTX_DAG_OWNER='Lapshin Nikita' AIRFLOW_CTX_DAG_ID='Nikita_Lapshin_experiment' AIRFLOW_CTX_TASK_ID='init' AIRFLOW_CTX_EXECUTION_DATE='2024-10-24T20:21:51.943577+00:00' AIRFLOW_CTX_TRY_NUMBER='2' AIRFLOW_CTX_DAG_RUN_ID='manual__2024-10-24T20:21:51.943577+00:00'
[2024-10-24T20:23:00.595+0000] {taskinstance.py:430} INFO - ::endgroup::
[2024-10-24T20:23:00.611+0000] {taskinstance.py:441} INFO - ::group::Post task execution logs
[2024-10-24T20:23:00.612+0000] {taskinstance.py:2905} ERROR - Task failed with exception
Traceback (most recent call last):
  File "/home/airflow/.local/lib/python3.10/site-packages/airflow/models/taskinstance.py", line 465, in _execute_task
    result = _execute_callable(context=context, **execute_callable_kwargs)
  File "/home/airflow/.local/lib/python3.10/site-packages/airflow/models/taskinstance.py", line 432, in _execute_callable
    return execute_callable(context=context, **execute_callable_kwargs)
  File "/home/airflow/.local/lib/python3.10/site-packages/airflow/models/baseoperator.py", line 401, in wrapper
    return func(self, *args, **kwargs)
  File "/home/airflow/.local/lib/python3.10/site-packages/airflow/operators/python.py", line 235, in execute
    return_value = self.execute_callable()
  File "/home/airflow/.local/lib/python3.10/site-packages/airflow/operators/python.py", line 252, in execute_callable
    return self.python_callable(*self.op_args, **self.op_kwargs)
  File "/opt/airflow/dags/HW2.py", line 49, in init
    configure_mlflow()
  File "/opt/airflow/dags/HW2.py", line 45, in configure_mlflow
    os.environ[key] = Variable.get(key)
  File "/home/airflow/.local/lib/python3.10/site-packages/airflow/models/variable.py", line 143, in get
    raise KeyError(f"Variable {key} does not exist")
KeyError: 'Variable MLFLOW_TRACKING_URI does not exist'
[2024-10-24T20:23:00.619+0000] {taskinstance.py:1206} INFO - Marking task as UP_FOR_RETRY. dag_id=Nikita_Lapshin_experiment, task_id=init, run_id=manual__2024-10-24T20:21:51.943577+00:00, execution_date=20241024T202151, start_date=20241024T202300, end_date=20241024T202300
[2024-10-24T20:23:00.626+0000] {standard_task_runner.py:110} ERROR - Failed to execute job 166 for task init ('Variable MLFLOW_TRACKING_URI does not exist'; 763)
[2024-10-24T20:23:00.668+0000] {local_task_job_runner.py:243} INFO - Task exited with return code 1
[2024-10-24T20:23:00.681+0000] {local_task_job_runner.py:222} INFO - ::endgroup::
