[2024-10-24T20:25:08.548+0000] {local_task_job_runner.py:120} INFO - ::group::Pre task execution logs
[2024-10-24T20:25:08.557+0000] {taskinstance.py:2076} INFO - Dependencies all met for dep_context=non-requeueable deps ti=<TaskInstance: Nikita_Lapshin_experiment.init manual__2024-10-24T20:21:51.943577+00:00 [queued]>
[2024-10-24T20:25:08.564+0000] {taskinstance.py:2076} INFO - Dependencies all met for dep_context=requeueable deps ti=<TaskInstance: Nikita_Lapshin_experiment.init manual__2024-10-24T20:21:51.943577+00:00 [queued]>
[2024-10-24T20:25:08.564+0000] {taskinstance.py:2306} INFO - Starting attempt 4 of 4
[2024-10-24T20:25:08.575+0000] {taskinstance.py:2330} INFO - Executing <Task(PythonOperator): init> on 2024-10-24 20:21:51.943577+00:00
[2024-10-24T20:25:08.590+0000] {standard_task_runner.py:64} INFO - Started process 841 to run task
[2024-10-24T20:25:08.595+0000] {standard_task_runner.py:90} INFO - Running: ['***', 'tasks', 'run', 'Nikita_Lapshin_experiment', 'init', 'manual__2024-10-24T20:21:51.943577+00:00', '--job-id', '168', '--raw', '--subdir', 'DAGS_FOLDER/HW2.py', '--cfg-path', '/tmp/tmpvt7u6b0b']
[2024-10-24T20:25:08.599+0000] {standard_task_runner.py:91} INFO - Job 168: Subtask init
[2024-10-24T20:25:08.681+0000] {task_command.py:426} INFO - Running <TaskInstance: Nikita_Lapshin_experiment.init manual__2024-10-24T20:21:51.943577+00:00 [running]> on host 701639cb5e9f
[2024-10-24T20:25:08.794+0000] {taskinstance.py:2648} INFO - Exporting env vars: AIRFLOW_CTX_DAG_OWNER='Lapshin Nikita' AIRFLOW_CTX_DAG_ID='Nikita_Lapshin_experiment' AIRFLOW_CTX_TASK_ID='init' AIRFLOW_CTX_EXECUTION_DATE='2024-10-24T20:21:51.943577+00:00' AIRFLOW_CTX_TRY_NUMBER='4' AIRFLOW_CTX_DAG_RUN_ID='manual__2024-10-24T20:21:51.943577+00:00'
[2024-10-24T20:25:08.797+0000] {taskinstance.py:430} INFO - ::endgroup::
[2024-10-24T20:25:08.834+0000] {taskinstance.py:441} INFO - ::group::Post task execution logs
[2024-10-24T20:25:08.835+0000] {taskinstance.py:2905} ERROR - Task failed with exception
Traceback (most recent call last):
  File "/home/airflow/.local/lib/python3.10/site-packages/airflow/models/taskinstance.py", line 465, in _execute_task
    result = _execute_callable(context=context, **execute_callable_kwargs)
  File "/home/airflow/.local/lib/python3.10/site-packages/airflow/models/taskinstance.py", line 432, in _execute_callable
    return execute_callable(context=context, **execute_callable_kwargs)
  File "/home/airflow/.local/lib/python3.10/site-packages/airflow/models/baseoperator.py", line 401, in wrapper
    return func(self, *args, **kwargs)
  File "/home/airflow/.local/lib/python3.10/site-packages/airflow/operators/python.py", line 235, in execute
    return_value = self.execute_callable()
  File "/home/airflow/.local/lib/python3.10/site-packages/airflow/operators/python.py", line 252, in execute_callable
    return self.python_callable(*self.op_args, **self.op_kwargs)
  File "/opt/airflow/dags/HW2.py", line 49, in init
    configure_mlflow()
  File "/opt/airflow/dags/HW2.py", line 45, in configure_mlflow
    os.environ[key] = Variable.get(key)
  File "/home/airflow/.local/lib/python3.10/site-packages/airflow/models/variable.py", line 143, in get
    raise KeyError(f"Variable {key} does not exist")
KeyError: 'Variable AWS_ACCESS_KEY_ID does not exist'
[2024-10-24T20:25:08.846+0000] {taskinstance.py:1206} INFO - Marking task as FAILED. dag_id=Nikita_Lapshin_experiment, task_id=init, run_id=manual__2024-10-24T20:21:51.943577+00:00, execution_date=20241024T202151, start_date=20241024T202508, end_date=20241024T202508
[2024-10-24T20:25:08.858+0000] {standard_task_runner.py:110} ERROR - Failed to execute job 168 for task init ('Variable AWS_ACCESS_KEY_ID does not exist'; 841)
[2024-10-24T20:25:08.898+0000] {local_task_job_runner.py:243} INFO - Task exited with return code 1
[2024-10-24T20:25:08.918+0000] {taskinstance.py:3503} INFO - 0 downstream tasks scheduled from follow-on schedule check
[2024-10-24T20:25:08.921+0000] {local_task_job_runner.py:222} INFO - ::endgroup::
